#The try block will generate an exception
#Because x is not defined

try:
    print(x)
except:
    print("Exception is occured")